# Java
## 예외처리
### 메서드에 예외 선언하기
**예외 처리 방법**
- try-catch문 사용
- 예외를 메서드에 선언

**메서드에 예외 선언**
- 메서드 선언부에 `throws` 사용해서 메서드 내에서 발생할 수 있는 예외 작성
- 예외가 여러 개 일때에는 쉼표로 구분

```Java
void method() throws Exception1, Exception2 ... {
}
```

- 예외를 처리하는 것이 아니라, 자신을 호출한 메서드에게 예외를 전달해 예외처리를 떠맡기는 것<br>
-> 결국 어느 한 곳에서는 반드시 try-catch문으로 예외처리 해야함
- 예외가 발생한 메서드A 내에서 예외를 처리하면, 메서드A를 호출하는 메서드는 예외가 발생했다는 사실조차 모른다
- `void method() throws Exception {} `: Exception은 모든 예외의 최고조상이기 때문에, 이 메서드는 모든 종류의 예외가 발생할 가능성이 있다는 뜻 (해당 예외뿐만 아니라 그 자손타입의 예외까지도 발생할 수 있다는 것을 고려하자)
- 메서드 사용자는 이 메서드를 사용하기 위해 어떤 예외들이 처리되어야하는지 쉽게 알수있음
- 메서드 사용하는 쪽에서 이에 대한 예외처리를 하도록 강요 <br>
-> 프로그래머들의 짐 덜어줌, 견고한 코드 작성 도와줌

**Java API에서 throws로 선언된 예외와 선언되어있지 않은 예외**
- Exception클래스의 자손들(RuntimeException클래스의 자손이 아닌): 반드시 처리해주어야 하는 예외이기 때문에, 메서드 선언부에 throws와 함께 선언되어 있음
- 발생할 수 있는 예외지만 RuntimeException클래스의 자손일 경우, 예외처리가 강제가 아니기 때문에 메서드 선언부에 적혀있지 않음

메서드에 예외 선언할 때 보통 RuntimeException클래스들은 적지 않는다. 적어도 문제가 되지는 않지만, 보통 반드시 처리해야 하는 예외들만 선언한다

예제 코드1
```Java
public class ExceptionEx12 {
    public static void main(String[] args) throws Exception {
        method1();
    }
    static void method1() throws Exception {
        method2();
    }
    static void method2() throws Exception {
        throw new Exception();
    }
}
```

실행 결과 1
```
Exception in thread "main" java.lang.Exception
	at Example.ExceptionEx12.method2(ExceptionEx12.java:11)
	at Example.ExceptionEx12.method1(ExceptionEx12.java:8)
	at Example.ExceptionEx12.main(ExceptionEx12.java:5)

Process finished with exit code 1
```
- 예외를 계속 전달하다가 제일 마지막에 있는 main 메서드에서도 예외가 처리되지 않으면 main 메서드마저 종료되어 프로그램 전체가 비정상적으로 종료됨
- 예외가 발생하는 순간, 해당 메서드는 즉시 종료
- 실행 결과는 예외가 발생한 메서드들도 call stack에 남아있는 것처럼 보이는데, 그 이유는 예외 정보 출력시 예외 발생 경로를 기록해서 보여주기 때문이다

위 결과에서 알 수 있는 사실
- 예외가 발생했을 때, 3개 메서드 모두 다 호출스택에 있었다
- 예외가 발생한 곳은 제일 윗 줄의 method2()이다
- main 메서드가 method1()을, method1()이 method2()를 호출했다
<br><br>
- 예외가 발생한 메서드 내에서 자체적으로 처리해도 되는 것은 메서드 내에서 try-catch문으로 처리한다
- 메서드 호출 시 넘겨받는 값을 다시 받아야 하는 경우 (예외가 발생하는 메서드 내에서 넘겨받는 값에 대해 해결이 안되는 경우): 예외를 메서드에 선언하고 호출한 메서드에서 예외 처리

예제 코드2
```Java
public class ExceptionEx12 {
    public static void main(String[] args) throws Exception {
        try {
            method1();
        } catch (Exception e) { }
    }
    static void method1() throws Exception {
        method2();
        System.out.println("hi"); // 실행x
    }
    static void method2() throws Exception {
        throw new Exception();
    }
}
```
- 위 코드에서 method1()의 System.out.println("hi");는 실행되지 않음
- method2()에서 발생한 예외가 method1()으로 전파되면서 method1()에도 예외가 발생해 method1()의 실행은 중단됨. 예외는 해당 메서드를 호출한 메서드(main())로 또 전파됨

**예외가 발생하면 실행 흐름이 바뀌는 이유**
1. 예외가 발생하면 해당 메서드의 실행이 중단된다
2. 중단된 이후에는 정상적인 실행 흐름을 따르지 않고, 가장 가까운 예외 처리기로 이동한다
3. 따라서 예외가 발생한 메서드의 나머지 코드는 실행되지 않는다

### finally 블럭
- 예외의 발생여부 상관없이 실행되어야 할 코드 포함시킬 목적으로 사용<br>
: 리소스 정리같은 작업 보장하기 위해 실행
- try-catch-finally 순서로 구성
```Java
try {
    // 예외 발생 가능성있는 문장
} catch (Exception1 e1) {
    // 예외처리 문장
} finally {
    // 예외 발생여부 관계없이 항상 수행되어야 하는 문장
}
```
- 예외 발생: try -> catch -> finally 순으로 실행
- 예외 발생x: try -> finally 순으로 실행

예제 코드1
```Java
public class ExceptionEx19 {
    public static void main(String[] args) {
       ExceptionEx19.method1();
        System.out.println("method1()의 수행을 마치고 main메서드로 돌아왔습니다."); // 실행
    }

    static void method1() {
        try {
            System.out.println("method1()이 호출되었습니다."); // 실행
            return; // 현재 실행중인 메서드 종료
        } catch (Exception e) {
            e.printStackTrace();
        } finally {
            System.out.println("method1()의 finally 블럭이 실행되었습니다."); // 실행
        }
        System.out.println("try-catch문을 빠져나옴"); // ①: Unreachable statement 컴파일 에러는 발생하지 않으나, 실행 x
    }
}
```

실행결과1
```
method1()이 호출되었습니다.
method1()의 finally 블럭이 실행되었습니다.
method1()의 수행을 마치고 main메서드로 돌아왔습니다.
```

- try블럭에서 return문이 실행돼도 finally블럭 문장들이 먼저 실행된 후에 현재 실행중인 메서드 종료
- catch블럭 수행중에 return문 만나도 finally 문장들은 수행된다
- catch블럭에 return문이 있으면, ① 영역(try-catch문 끝난 후)에 코드 작성시 Unreachable statement 컴파일 에러 발생

예제 코드2
```Java
public class ExceptionEx19 {
    public static void main(String[] args) throws Exception {
        method1();
        System.out.println("method1()의 수행을 마치고 main메서드로 돌아왔습니다."); // 실행 x
    }

    static void method1() throws Exception {
        try {
            System.out.println("method1()이 호출되었습니다.");
            throw new Exception("exception발생!");
        }  finally {
            System.out.println("method1()의 finally 블럭이 실행되었습니다."); 
        }
    }
}
```

실행 결과2
```
method1()이 호출되었습니다.
method1()의 finally 블럭이 실행되었습니다.
Exception in thread "main" java.lang.Exception: exception발생!
	at Example.ExceptionEx19.method1(ExceptionEx19.java:12)
	at Example.ExceptionEx19.main(ExceptionEx19.java:5)

Process finished with exit code 1
```
- try블럭에서 예외가 발생해도, finally 블록은 반드시 실행되고 난 뒤에 예외가 호출자에게 전달된다


### 자동 자원 반환: try-with-resources문
- try-catch문의 변형 
- 입출력에 사용되는 클래스 중, 사용했던 자원 반환을 위해 사용한 후 꼭 닫아줘야 하는 것들이 있는데, 이런 클래스를 사용할 때 유용

```Java
try {
    fis = new FileInputStream("score.dat");
    dis = new DataInputStream(fis);
} catch (IOException ie) {
    ie.printStackTrace();
} finally {
    dis.close(); // 작업 중에 예외가 발생하더라도, dis가 닫히도록 finally 블럭에 넣음
}
```
- 파일로부터 데이터를 읽는 코드인데, 데이터 읽는 도중 예외가 발생해도 DataInputStream이 닫히도록 finally에서 `close()`한다 <br>
: 문제는 `close()`가 예외를 발생시킬 수도 있는 것<br>
-> 해결을 위해 아래 코드처럼 수정해야 함

```Java
try {
    fis = new FileInputStream("score.dat");
    dis = new DataInputStream(fis);
} catch (IOException ie) {
    ie.printStackTrace();
} finally {
    try {
        if (dis != null) dis.close();
    } catch (IOException ie) {
       ie.printStackTrace();
    }
}
```
- finally 블럭 안에 try-catch문 추가해서 close()에서 발생할 수 있는 예외 처리<br>
-> 코드 복잡<br>
-> try블럭과 finally블럭에서 모두 예외 발생하면 try블럭의 예외는 무시됨 <br>
-> 개선위해 try-with-resources문 사용

**왜 try블럭과 finally블럭에서 모두 예외 발생하면 try블럭의 예외는 무시될까?**
- 자바는 한 번에 하나의 예외만 처리 가능
- try 블럭에서 예외 발생시 그 예외는 일단 처리 대기 상태가 되고, 예외가 발생했더라도 finally 블럭은 항상 실행되므로 finally 블럭으로 흐름이 이동한다
- finally 블럭에서 새로운 예외가 발생하면, 이전에 try 블럭에서 발생했던 예외는 더 이상 처리되지 않고 무시<br>
: finally 블럭에서 발생한 예외가 더 "가까운 예외"로 간주되며, 이전 try 블럭에서 발생한 예외는 덮어씌워져 호출자에게 전달되지 않는다
- finally 블럭에서 발생한 예외로 인해 try 블럭의 예외가 사라지는 문제를 방지하려면, finally 블럭 내부에서 발생하는 예외를 처리해야한다

**try-with-resources문 사용한 개선**
```Java
try (FileInputStream fis = new FileInputStream("score.dat"); DataInputStream dis = new DataInputStream(fis)) {
    while (true) {
        score = dis.readInt();
        System.out.println(score);
        sum += score;
    }
} catch (EOFException e) {
    System.out.println("점수의 총합은 " + sum + "입니다.");
} catch (IOException ie) {
    ie.printStackTrace();
}
```

- try-with-resources문 괄호()안에 객체 생성 문장 넣으면, 이 객체는 따로 `close()` 호출안해도 try 블럭 벗어나는 순간 자동으로 `close()`가 호출되고, 그 후 catch, finally 블럭 수행됨
- try블럭 괄호()안에 변수 선언도 가능하며, 선언된 변수는 try 블럭 내에서만 사용 가능
- try-with-resources문에 의해 자동으로 객체의 close()가 호출될 수 있으려면 클래스가 AutoCloseable 인터페이스를 구현한 것이어야 한다

```Java
public interface AutoCloseable {
    void close() throws Exception;
}
```

코드 예제 1
```Java
public class ExceptionEx20 {
    public static void main(String[] args) {
         try (CloseableResource cr = new CloseableResource()) {
             cr.exceptionWork(false); // 예외 발생하지 않음
         } catch (WorkException e) {
             e.printStackTrace();
         } catch (CloseException e) {
             e.printStackTrace();
         }
        System.out.println();

         try (CloseableResource cr = new CloseableResource()) {
             cr.exceptionWork(true); // 예외 발생
         } catch (WorkException e) {
             e.printStackTrace();
         } catch (CloseException e) {
             e.printStackTrace();
         }
    }
}

class CloseableResource implements AutoCloseable {
    public void exceptionWork (boolean exception) throws WorkException {
        System.out.println("exceptionWork("+exception+")가 호출됨");

        if (exception) {
            throw new WorkException("WorkException발생!!!");
        }
    }

    public void close() throws CloseException {
        System.out.println("close()가 호출됨");
        throw new CloseException("CloseException발생!!!");
    }
}

class WorkException extends Exception {
    WorkException(String msg) {super(msg);}
}

class CloseException extends Exception {
    CloseException(String msg) {super(msg);}
}
```

결과 1
```
exceptionWork(false)가 호출됨
close()가 호출됨
Example.CloseException: CloseException발생!!!
	at Example.CloseableResource.close(ExceptionEx20.java:35)
	at Example.ExceptionEx20.main(ExceptionEx20.java:7)

exceptionWork(true)가 호출됨
close()가 호출됨
Example.WorkException: WorkException발생!!!
	at Example.CloseableResource.exceptionWork(ExceptionEx20.java:29)
	at Example.ExceptionEx20.main(ExceptionEx20.java:15)
	Suppressed: Example.CloseException: CloseException발생!!!
		at Example.CloseableResource.close(ExceptionEx20.java:35)
		at Example.ExceptionEx20.main(ExceptionEx20.java:14)
```
- try-with-resources 문법에서 리소스를 닫을 때 발생하는 자동 호출된 `close()`에서 예외가 발생하면, 억제된(suppressed)예외로 처리된다
- try 블록에서 발생한 예외는 주 예외로 간주된다
- 억제된 예외는 주 예외에 포함되며, 주 예외에서 참고할 수 있다
- 이 메커니즘은 리소스를 닫는 과정에서 발생하는 예외가 try 블록에서 발생한 주 예외를 덮어쓰지 않도록 설계되어있다
- AutoCloseable을 구현한 클래스이더라도, 기존의 try-catch문 사용해서 finally블럭에서 `close()`를 수동 호출하면 일반 예외 규칙이 적용되어 `close()`에서 발생한 예외가 이전의 예외를 덮어쓴다